Workbook

Sheet Sheet1
A1: 401.3307 | B1: 422.9236 | C1: 410.69215 | D1: 402.67127 | E1: 398.87507 | F1: 361.0851 | G1: 306.19942 | H1: 404.46069 | I1: 426.21937 | J1: 413.89006 | K1: 405.80424 | L1: 401.97603 | M1: 363.89005 | N1: 308.57613 | O1: 407.59762 | P1: 429.52244 | Q1: 417.09505 | R1: 408.94414 | S1: 405.08386 | T1: 366.70121 | U1: 310.95809 | V1: 410.74148 | W1: 432.83281 | X1: 420.30712 | Y1: 412.09097 | Z1: 408.19854 | AA1: 369.51856 | AB1: 313.34531 | AC1: 413.89227 | AD1: 436.15047 | AE1: 423.52627 | AF1: 415.24473 | AG1: 411.34548 | AH1: 372.38806 | AI1: 315.79616 | AJ1: 417.15271 | AK1: 439.61062 | AL1: 426.90988 | AM1: 418.58529 | AN1: 414.65193 | AO1: 375.37888 | AP1: 318.33036 | AQ1: 420.49751 | AR1: 443.13257 | AS1: 430.32725 | AT1: 421.93326 | AU1: 417.96571 | AV1: 378.37633 | AW1: 320.87018 | AX1: 423.84972 | AY1: 446.66232 | AZ1: 433.7522 | BA1: 425.28865 | BB1: 421.28682 | BC1: 381.3804 | BD1: 323.41561 | BE1: 427.20933 | BF1: 450.19988 | BG1: 437.1847 | BH1: 428.65144 | BI1: 424.61526 | BJ1: 383.36358 | BK1: 324.22557 | BL1: 427.12979 | BM1: 448.90703 | BN1: 434.75734 | BO1: 425.12459 | BP1: 419.98767 | BQ1: 379.17728 | BR1: 320.67803 | BS1: 422.44703 | BT1: 443.97572 | BU1: 429.97195 | BV1: 420.43589 | BW1: 415.34636 | BX1: 374.97858 | BY1: 317.11998 | BZ1: 417.7504 | CA1: 439.02981 | CB1: 425.1724 | CC1: 415.73332 | CD1: 410.69133 | CE1: 370.76748 | CF1: 313.55143 | CG1: 413.03991 | CH1: 434.06932 | CI1: 420.3587 | CJ1: 411.01688 | CK1: 406.02258 | CL1: 366.54396 | CM1: 309.97236 | CN1: 408.31555 | CO1: 431.93372 | CP1: 421.04049 | CQ1: 414.38219 | CR1: 412.02265 | CS1: 374.38498 | CT1: 318.66094 | CU1: 422.48128 | CV1: 446.85039 | CW1: 435.51489 | CX1: 428.56327 | CY1: 426.05951 | CZ1: 387.08247 | DA1: 329.42034 | DB1: 436.68282 | DC1: 461.80478 | DD1: 450.02587 | DE1: 442.78016 | DF1: 440.13182 | DG1: 399.812 | DH1: 340.20688 | DI1: 450.92018 | DJ1: 476.79686 | DK1: 464.57342 | DL1: 457.03288 | DM1: 454.23957 | DN1: 412.57359 | DO1: 351.02058 | DP1: 465.19337 | DQ1: 491.82665 | DR1: 479.15754 | DS1: 472.77241 | DT1: 471.25474 | DU1: 429.26346 | DV1: 366.26269 | DW1: 486.76278 | DX1: 516.0669 | DY1: 504.16067 | DZ1: 497.26892 | EA1: 495.50222 | EB1: 451.19735 | EC1: 384.84874 | ED1: 511.29495 | EE1: 541.89962 | EF1: 529.2275 | EG1: 521.82783 | EH1: 519.81143 | EI1: 473.18706 | EJ1: 403.48207 | EK1: 535.88951 | EL1: 567.79801 | EM1: 554.35805 | EN1: 546.44914 | EO1: 544.18239 | EP1: 495.2326 | EQ1: 422.1627 | ER1: 560.54647 | ES1: 593.76209 | ET1: 579.55231 | EU1: 571.13284 | EV1: 568.61508 | EW1: 517.33397 | EX1: 440.38086 | EY1: 583.92039 | EZ1: 617.66708 | FA1: 602.06173 | FB1: 592.51347 | FC1: 589.11272 | FD1: 535.2739 | FE1: 455.58247 | FF1: 603.98523 | FG1: 638.79551 | FH1: 622.56362 | FI1: 612.5998 | FJ1: 608.9947 | FK1: 553.25871 | FL1: 470.82208 | FM1: 624.10022 | FN1: 659.97672 | FO1: 643.11671 | FP1: 632.73628 | FQ1: 628.92631 | FR1: 571.28838 | FS1: 486.09971 | FT1: 644.26536 | FU1: 681.21072 | FV1: 663.72101 | FW1: 652.92291 | FX1: 648.90754 | FY1: 589.36292 | FZ1: 501.41534 | GA1: 664.48065 | GB1: 699.58259 | GC1: 678.7205 | GD1: 664.84908 | GE1: 657.97218 | GF1: 595.08473 | GG1: 504.16485 | GH1: 665.34032 | GI1: 700.48751 | GJ1: 679.59828 | GK1: 665.70875 | GL1: 658.82281 | GM1: 595.85391 | GN1: 504.81639 | GO1: 666.19999 | GP1: 701.39243 | GQ1: 680.47605 | GR1: 666.56843 | GS1: 659.67343 | GT1: 596.6231 | GU1: 505.46793 | GV1: 667.05967 | GW1: 702.29735 | GX1: 681.35382 | GY1: 667.4281 | GZ1: 660.52406 | HA1: 597.39228 | HB1: 506.11948 | HC1: 667.91934 | HD1: 703.20227 | HE1: 682.2316 | HF1: 668.28778 | HG1: 660.23176 | HH1: 596.09408 | HI1: 504.14375 | HJ1: 664.15612 | HK1: 698.02331 | HL1: 676.02644 | HM1: 661.05292 | HN1: 653.07012 | HO1: 589.61548 | HP1: 498.65374 | HQ1: 656.90938 | HR1: 690.39204 | HS1: 668.62107 | HT1: 653.79727 | HU1: 645.88791 | HV1: 583.11826 | HW1: 493.14796 | HX1: 649.64185 | HY1: 682.73888 | HZ1: 661.19447 | IA1: 646.52083 | IB1: 638.68511 | IC1: 576.60244 | ID1: 487.62643 | IE1: 642.35352 | IF1: 675.06382 | IG1: 653.74663 | IH1: 639.22358 | II1: 631.46174 | IJ1: 570.06801 | IK1: 482.08913 | IL1: 634.2054 | IM1: 665.60027 | IN1: 643.70668 | IO1: 628.54777 | IP1: 620.064 | IQ1: 559.00684 | IR1: 472.08017 | IS1: 620.99402 | IT1: 651.68816 | IU1: 630.20671 | IV1: 615.32103 | IW1: 606.97143 | IX1: 547.16324 | IY1: 462.04406 | IZ1: 607.74682 | JA1: 637.73835 | JB1: 616.67017 | JC1: 602.05848 | JD1: 593.84342 | JE1: 535.28759 | JF1: 451.9808 | JG1: 594.46379 | JH1: 623.75084 | JI1: 603.09705 | JJ1: 588.7601 | JK1: 580.67996 | JL1: 523.37988 | JM1: 441.8904 | JN1: 581.14495 | JO1: 609.72561 | JP1: 588.75854 | JQ1: 573.99805 | JR1: 565.36144 | JS1: 508.88409 | JT1: 429.06596 | JU1: 563.50361 | JV1: 590.39739 | JW1: 570.00308 | JX1: 555.62237 | JY1: 547.17233 | JZ1: 492.43029 | KA1: 415.12337 | KB1: 545.10019 | KC1: 571.01808 | KD1: 551.19807 | KE1: 537.19816 | KF1: 528.9352 | KG1: 475.93306 | KH1: 401.14399 | KI1: 526.64825 | KJ1: 551.58768 | KK1: 532.34351 | KL1: 518.72542 | KM1: 510.65005 | KN1: 459.39241 | KO1: 387.12784 | KP1: 508.14778 | KQ1: 532.1062 | KR1: 513.4394 | KS1: 500.20415 | KT1: 492.31688 | KU1: 445.62261 | KV1: 377.84345 | KW1: 499.03824 | KX1: 525.8244 | KY1: 510.55518 | KZ1: 500.52351 | LA1: 495.74501 | LB1: 448.72342 | LC1: 380.4708 | LD1: 502.50591 | LE1: 529.47566 | LF1: 514.09794 | LG1: 503.99424 | LH1: 499.18022 | LI1: 451.83065 | LJ1: 383.10358 | LK1: 505.98074 | LL1: 533.13445 | LM1: 517.64802 | LN1: 507.47214 | LO1: 502.62252 | LP1: 454.94429 | LQ1: 385.74179 | LR1: 509.46273 | LS1: 536.80078 | LT1: 521.20541 | LU1: 510.95721 | LV1: 506.07192 | LW1: 458.06434 | LX1: 388.38543 | LY1: 509.78949 | LZ1: 533.81578 | MA1: 515.0797 | MB1: 501.79302 | MC1: 493.87159 | MD1: 444.19844 | ME1: 374.23904 | MF1: 491.11718 | MG1: 514.15342 | MH1: 496.00013 | MI1: 483.09991 | MJ1: 475.36839 | MK1: 427.46062 | ML1: 360.05587 | MM1: 472.39634 | MN1: 494.43998 | MO1: 476.87101 | MP1: 464.35827 | MQ1: 456.81718 | MR1: 410.67938 | MS1: 345.83592 | MT1: 453.62698 | MU1: 474.67545 | MV1: 457.69234 | MW1: 445.56811 | MX1: 438.21794 | MY1: 393.85472 | MZ1: 331.57919 | NA1: 457.69377 | NB1: 432.11685
A2: 366.93385 | B2: 386.32003 | C2: 374.80208 | D2: 367.14438 | E2: 363.34914 | F2: 328.62318 | G2: 278.41636 | H2: 367.42509 | I2: 386.83712 | J2: 375.30367 | K2: 367.63562 | L2: 363.83521 | M2: 329.06272 | N2: 278.78867 | O2: 367.91633 | P2: 387.35422 | Q2: 375.80525 | R2: 368.12687 | S2: 364.32128 | T2: 329.50225 | U2: 279.16098 | V2: 368.40758 | W2: 387.87132 | X2: 376.30683 | Y2: 368.61811 | Z2: 364.80736 | AA2: 329.94178 | AB2: 279.53329 | AC2: 368.89882 | AD2: 388.38842 | AE2: 376.80842 | AF2: 369.10935 | AG2: 365.68706 | AH2: 331.09334 | AI2: 280.81046 | AJ2: 370.98226 | AK2: 391.00091 | AL2: 379.74951 | AM2: 372.38853 | AN2: 368.93277 | AO2: 334.02924 | AP2: 283.29814 | AQ2: 374.26567 | AR2: 394.45825 | AS2: 383.10421 | AT2: 375.67512 | AU2: 372.18581 | AV2: 336.97177 | AW2: 285.79144 | AX2: 377.5565 | AY2: 397.92339 | AZ2: 386.46647 | BA2: 378.96912 | BB2: 375.44618 | BC2: 339.92092 | BD2: 288.29035 | BE2: 380.85473 | BF2: 401.39633 | BG2: 389.83631 | BH2: 382.27053 | BI2: 378.71389 | BJ2: 342.18399 | BK2: 289.6211 | BL2: 381.83682 | BM2: 401.61533 | BN2: 389.2581 | BO2: 380.92961 | BP2: 376.62033 | BQ2: 340.28998 | BR2: 288.01601 | BS2: 379.71802 | BT2: 399.38396 | BU2: 387.09266 | BV2: 378.80784 | BW2: 374.5199 | BX2: 338.38978 | BY2: 286.40568 | BZ2: 377.59228 | CA2: 397.1453 | CB2: 384.92015 | CC2: 376.67912 | CD2: 372.41262 | CE2: 336.48337 | CF2: 284.79009 | CG2: 375.45961 | CH2: 394.89934 | CI2: 382.74055 | CJ2: 374.54348 | CK2: 370.29848 | CL2: 334.57076 | CM2: 283.16924 | CN2: 373.32 | CO2: 394.27055 | CP2: 383.70594 | CQ2: 377.03238 | CR2: 374.28892 | CS2: 339.56113 | CT2: 288.56744 | CU2: 381.98836 | CV2: 403.39837 | CW2: 392.56307 | CX2: 385.70995 | CY2: 382.87819 | CZ2: 347.33077 | DA2: 295.15111 | DB2: 390.67822 | DC2: 412.54882 | DD2: 401.44214 | DE2: 394.40902 | DF2: 391.48873 | DG2: 355.11963 | DH2: 301.75107 | DI2: 399.38956 | DJ2: 421.72189 | DK2: 410.34315 | DL2: 403.12958 | DM2: 400.12053 | DN2: 362.92773 | DO2: 308.36731 | DP2: 408.1224 | DQ2: 430.91759 | DR2: 419.26611 | DS2: 414.10492 | DT2: 413.19398 | DU2: 376.75192 | DV2: 321.77404 | DW2: 428.05153 | DX2: 454.25407 | DY2: 444.19106 | DZ2: 438.52486 | EA2: 437.36569 | EB2: 398.6173 | EC2: 340.30205 | ED2: 452.50713 | EE2: 480.00619 | EF2: 469.17971 | EG2: 463.0072 | EH2: 461.59914 | EI2: 420.5385 | EJ2: 358.87736 | EK2: 477.02512 | EL2: 505.82399 | EM2: 494.23208 | EN2: 487.55194 | EO2: 485.89433 | EP2: 442.51553 | EQ2: 377.49995 | ER2: 501.60551 | ES2: 531.70746 | ET2: 519.34815 | EU2: 512.15907 | EV2: 510.25126 | EW2: 464.54838 | EX2: 395.66007 | EY2: 524.90285 | EZ2: 555.53183 | FA2: 541.77937 | FB2: 533.4631 | FC2: 530.6731 | FD2: 482.41978 | FE2: 410.80362 | FF2: 544.89108 | FG2: 576.57962 | FH2: 562.20304 | FI2: 553.47282 | FJ2: 550.47929 | FK2: 500.33604 | FL2: 425.98517 | FM2: 564.92947 | FN2: 597.6802 | FO2: 582.67791 | FP2: 573.5327 | FQ2: 570.33509 | FR2: 518.29716 | FS2: 441.20474 | FT2: 585.018 | FU2: 618.83356 | FV2: 603.20399 | FW2: 593.64272 | FX2: 590.24052 | FY2: 536.30316 | FZ2: 456.46231 | GA2: 605.15668 | GB2: 636.31878 | GC2: 616.56133 | GD2: 603.19433 | GE2: 596.19713 | GF2: 538.5284 | GG2: 455.66863 | GH2: 600.57391 | GI2: 631.49273 | GJ2: 611.87804 | GK2: 598.60562 | GL2: 591.65475 | GM2: 534.41917 | GN2: 452.18636 | GO2: 595.97727 | GP2: 626.65208 | GQ2: 607.18058 | GR2: 594.00304 | GS2: 587.09866 | GT2: 530.29752 | GU2: 448.69359 | GV2: 591.36677 | GW2: 621.79683 | GX2: 602.46897 | GY2: 589.38659 | GZ2: 582.52885 | HA2: 526.16348 | HB2: 445.1903 | HC2: 586.7424 | HD2: 616.92699 | HE2: 597.7432 | HF2: 584.75628 | HG2: 578.3263 | HH2: 522.70615 | HI2: 442.55227 | HJ2: 583.64514 | HK2: 614.07053 | HL2: 595.36427 | HM2: 582.8103 | HN2: 576.39982 | HO2: 520.96324 | HP2: 441.07517 | HQ2: 581.6952 | HR2: 612.01691 | HS2: 593.37126 | HT2: 580.85739 | HU2: 574.46649 | HV2: 519.21412 | HW2: 439.59282 | HX2: 579.73832 | HY2: 609.956 | HZ2: 591.37116 | IA2: 578.89754 | IB2: 572.52629 | IC2: 517.4588 | ID2: 438.10521 | IE2: 577.77451 | IF2: 607.88779 | IG2: 589.36399 | IH2: 576.93076 | II2: 570.57923 | IJ2: 515.69728 | IK2: 436.61234 | IL2: 574.59047 | IM2: 603.25749 | IN2: 583.63183 | IO2: 570.10117 | IP2: 562.61826 | IQ2: 507.41007 | IR2: 428.67027 | IS2: 564.10724 | IT2: 592.21821 | IU2: 572.91955 | IV2: 559.60566 | IW2: 552.22918 | IX2: 498.01203 | IY2: 420.70647 | IZ2: 553.59536 | JA2: 581.14876 | JB2: 562.178 | JC2: 549.0815 | JD2: 541.81175 | JE2: 488.58835 | JF2: 412.72095 | JG2: 543.05483 | JH2: 570.04915 | JI2: 551.4072 | JJ2: 538.52868 | JK2: 531.36597 | JL2: 479.13903 | JM2: 404.71372 | JN2: 532.48563 | JO2: 558.91938 | JP2: 539.46751 | JQ2: 525.71454 | JR2: 517.57748 | JS2: 465.66732 | JT2: 392.45215 | JU2: 515.18492 | JV2: 539.52636 | JW2: 520.64921 | JX2: 507.27731 | JY2: 499.32747 | JZ2: 449.15845 | KA2: 378.46291 | KB2: 496.71996 | KC2: 520.08226 | KD2: 501.78135 | KE2: 488.79155 | KF2: 481.02943 | KG2: 432.60615 | KH2: 364.43689 | KI2: 478.20647 | KJ2: 500.58708 | KK2: 482.86395 | KL2: 470.25726 | KM2: 462.68338 | KN2: 416.01043 | KO2: 350.37408 | KP2: 459.64445 | KQ2: 481.04081 | KR2: 463.89699 | KS2: 451.67444 | KT2: 444.28931 | KU2: 402.18558 | KV2: 341.04309 | KW2: 450.47343 | KX2: 474.69432 | KY2: 460.95005 | KZ2: 451.93239 | LA2: 447.6567 | LB2: 405.23147 | LC2: 343.62391 | LD2: 453.87972 | LE2: 478.28096 | LF2: 464.43013 | LG2: 455.34174 | LH2: 451.03118 | LI2: 408.28378 | LJ2: 346.21017 | LK2: 457.29316 | LL2: 481.87514 | LM2: 467.91753 | LN2: 458.75826 | LO2: 454.41274 | LP2: 411.34249 | LQ2: 348.80186 | LR2: 460.71377 | LS2: 485.47686 | LT2: 471.41225 | LU2: 462.18194 | LV2: 457.8014 | LW2: 414.40761 | LX2: 351.39898 | LY2: 461.37278 | LZ2: 483.2561 | MA2: 466.43007 | MB2: 454.53177 | MC2: 447.48921 | MD2: 402.60192 | ME2: 339.29667 | MF2: 445.39853 | MG2: 466.43484 | MH2: 450.10738 | MI2: 438.53968 | MJ2: 431.65958 | MK2: 388.28257 | ML2: 327.16285 | MM2: 429.38267 | MN2: 449.56979 | MO2: 433.74221 | MP2: 422.506 | MQ2: 415.7888 | MR2: 373.92602 | MS2: 314.99749 | MT2: 413.32522 | MU2: 432.66095 | MV2: 417.33458 | MW2: 406.43073 | MX2: 399.87685 | MY2: 359.53224 | MZ2: 302.80061 | NA2: 418.13282 | NB2: 394.92292
A3: 344.00322 | B3: 362.56735 | C3: 352.13541 | D3: 345.31092 | E3: 342.10766 | F3: 309.74307 | G3: 262.70139 | H3: 347.0565 | I3: 365.78237 | J3: 355.25499 | K3: 348.36717 | L3: 345.13272 | M3: 312.47938 | N3: 265.01996 | O3: 350.11671 | P3: 369.00469 | Q3: 358.38164 | R3: 351.43035 | S3: 348.16464 | T3: 315.22189 | U3: 267.34378 | V3: 353.18386 | W3: 372.2343 | X3: 361.51538 | Y3: 354.50047 | Z3: 351.20342 | AA3: 317.97061 | AB3: 269.67286 | AC3: 356.25793 | AD3: 375.47121 | AE3: 364.6562 | AF3: 357.57752 | AG3: 353.48717 | AH3: 319.3474 | AI3: 270.25582 | AJ3: 356.25724 | AK3: 374.65979 | AL3: 363.08243 | AM3: 355.26545 | AN3: 351.1984 | AO3: 317.27681 | AP3: 268.50111 | AQ3: 353.94094 | AR3: 372.22046 | AS3: 360.71521 | AT3: 352.94597 | AU3: 348.90229 | AV3: 315.1996 | AW3: 266.74078 | AX3: 351.61723 | AY3: 369.77333 | AZ3: 358.34041 | BA3: 350.61908 | BB3: 346.59884 | BC3: 313.11575 | BD3: 264.97484 | BE3: 349.28611 | BF3: 367.3184 | BG3: 355.95805 | BH3: 348.28478 | BI3: 344.28807 | BJ3: 311.38318 | BK3: 263.80974 | BL3: 348.14808 | BM3: 366.54092 | BN3: 355.61187 | BO3: 348.34546 | BP3: 344.74376 | BQ3: 311.79525 | BR3: 264.15878 | BS3: 348.60862 | BT3: 367.0257 | BU3: 356.0821 | BV3: 348.806 | BW3: 345.19945 | BX3: 312.20731 | BY3: 264.50782 | BZ3: 349.06916 | CA3: 367.51048 | CB3: 356.55234 | CC3: 349.26654 | CD3: 345.65514 | CE3: 312.61937 | CF3: 264.85686 | CG3: 349.5297 | CH3: 367.99526 | CI3: 357.02257 | CJ3: 349.72708 | CK3: 346.11084 | CL3: 313.03143 | CM3: 265.2059 | CN3: 349.99024 | CO3: 370.11772 | CP3: 360.67052 | CQ3: 354.85678 | CR3: 352.72771 | CS3: 320.4089 | CT3: 272.6364 | CU3: 361.35369 | CV3: 382.08356 | CW3: 372.28157 | CX3: 366.23252 | CY3: 363.98775 | CZ3: 330.59452 | DA3: 281.26732 | DB3: 372.7458 | DC3: 394.07956 | DD3: 383.92187 | DE3: 377.63691 | DF3: 375.27615 | DG3: 340.80577 | DH3: 289.91996 | DI3: 384.16657 | DJ3: 406.10573 | DK3: 395.59143 | DL3: 389.06995 | DM3: 386.59289 | DN3: 351.04266 | DO3: 298.59431 | DP3: 395.61599 | DQ3: 418.16206 | DR3: 407.29025 | DS3: 401.61676 | DT3: 400.08577 | DU3: 364.21895 | DV3: 310.58182 | DW3: 412.52367 | DX3: 437.10828 | DY3: 426.78271 | DZ3: 420.71425 | EA3: 418.98909 | EB3: 381.31857 | EC3: 325.07146 | ED3: 431.64888 | EE3: 457.24739 | EF3: 446.32471 | EG3: 439.86026 | EH3: 437.94042 | EI3: 398.46162 | EJ3: 339.59789 | EK3: 450.82262 | EL3: 477.43757 | EM3: 465.91627 | EN3: 459.0548 | EO3: 456.93978 | EP3: 415.64809 | EQ3: 354.16109 | ER3: 470.0449 | ES3: 497.67884 | ET3: 485.55738 | EU3: 478.29787 | EV3: 475.98715 | EW3: 432.87798 | EX3: 368.82841 | EY3: 489.4934 | EZ3: 518.25183 | FA3: 505.61106 | FB3: 498.03398 | FC3: 495.61043 | FD3: 450.7083 | FE3: 383.93716 | FF3: 509.43573 | FG3: 539.2513 | FH3: 525.98786 | FI3: 517.9978 | FJ3: 515.37119 | FK3: 468.58349 | FL3: 399.08393 | FM3: 529.42821 | FN3: 560.30355 | FO3: 546.41587 | FP3: 538.01177 | FQ3: 535.18158 | FR3: 486.50355 | FS3: 414.2687 | FT3: 549.47084 | FU3: 581.40859 | FV3: 566.89507 | FW3: 558.07589 | FX3: 555.04159 | FY3: 504.46847 | FZ3: 429.49148 | GA3: 569.56361 | GB3: 599.24846 | GC3: 580.98744 | GD3: 568.73046 | GE3: 562.46875 | GF3: 508.3665 | GG3: 430.40542 | GH3: 567.61761 | GI3: 597.19899 | GJ3: 578.99845 | GK3: 566.78149 | GL3: 560.53931 | GM3: 506.62091 | GN3: 428.92605 | GO3: 565.66468 | GP3: 595.14223 | GQ3: 577.00238 | GR3: 564.82558 | GS3: 558.60302 | GT3: 504.86911 | GU3: 427.44143 | GV3: 563.70481 | GW3: 593.07817 | GX3: 574.99923 | GY3: 562.86274 | GZ3: 556.65986 | HA3: 503.11112 | HB3: 425.95155 | HC3: 561.73801 | HD3: 591.00681 | HE3: 572.989 | HF3: 560.89297 | HG3: 554.70984 | HH3: 501.34692 | HI3: 424.45642 | HJ3: 559.76428 | HK3: 588.92816 | HL3: 570.97169 | HM3: 558.91627 | HN3: 552.75297 | HO3: 499.57651 | HP3: 422.95603 | HQ3: 557.78361 | HR3: 586.8422 | HS3: 568.9473 | HT3: 556.93263 | HU3: 550.78923 | HV3: 497.79991 | HW3: 421.45039 | HX3: 555.79601 | HY3: 584.74895 | HZ3: 566.91584 | IA3: 554.94206 | IB3: 548.81863 | IC3: 496.0171 | ID3: 419.9395 | IE3: 553.80148 | IF3: 582.6484 | IG3: 564.87729 | IH3: 552.94456 | II3: 546.84118 | IJ3: 494.22809 | IK3: 418.42335 | IL3: 550.5867 | IM3: 577.98574 | IN3: 559.11374 | IO3: 546.0842 | IP3: 538.84976 | IQ3: 485.91334 | IR3: 410.45794 | IS3: 540.07269 | IT3: 566.91405 | IU3: 548.37002 | IV3: 535.55791 | IW3: 528.43022 | IX3: 476.48775 | IY3: 402.47081 | IZ3: 529.53002 | JA3: 555.81219 | JB3: 537.59704 | JC3: 525.00296 | JD3: 517.98232 | JE3: 467.03652 | JF3: 394.46196 | JG3: 518.95869 | JH3: 544.68017 | JI3: 526.7948 | JJ3: 514.41935 | JK3: 507.50607 | JL3: 457.55966 | JM3: 386.43139 | JN3: 508.35871 | JO3: 533.51799 | JP3: 514.82367 | JQ3: 501.57441 | JR3: 493.6871 | JS3: 444.06037 | JT3: 374.14646 | JU3: 491.02717 | JV3: 514.09251 | JW3: 495.97387 | JX3: 483.10633 | JY3: 475.40656 | JZ3: 427.5239 | KA3: 360.13384 | KB3: 472.53136 | KC3: 494.61594 | KD3: 477.07452 | KE3: 464.58973 | KF3: 457.078 | KG3: 410.944 | KH3: 346.08443 | KI3: 453.98702 | KJ3: 475.08828 | KK3: 458.12561 | KL3: 446.02459 | KM3: 438.70143 | KN3: 394.32068 | KO3: 331.99825 | KP3: 435.39415 | KQ3: 455.50954 | KR3: 439.12716 | KS3: 427.41092 | KT3: 420.27684 | KU3: 380.46825 | KV3: 322.64391 | KW3: 426.19236 | KX3: 449.13068 | KY3: 436.14884 | KZ3: 427.63817 | LA3: 423.61387 | LB3: 383.48669 | LC3: 325.20148 | LD3: 429.56796 | LE3: 452.68502 | LF3: 439.5976 | LG3: 431.01684 | LH3: 426.95798 | LI3: 386.51154 | LJ3: 327.76449 | LK3: 432.95072 | LL3: 456.24691 | LM3: 443.05367 | LN3: 434.40267 | LO3: 430.30919 | LP3: 389.54281 | LQ3: 330.33292 | LR3: 436.34065 | LS3: 459.81633 | LT3: 446.51706 | LU3: 437.79567 | LV3: 433.66749 | LW3: 392.58048 | LX3: 332.90679 | LY3: 436.96896 | LZ3: 457.56323 | MA3: 441.50349 | MB3: 430.11474 | MC3: 423.32484 | MD3: 380.74722 | ME3: 320.78112 | MF3: 420.96388 | MG3: 440.70952 | MH3: 425.14933 | MI3: 414.09183 | MJ3: 407.46471 | MK3: 366.40029 | ML3: 308.62393 | MM3: 404.9172 | MN3: 423.81202 | MO3: 408.75269 | MP3: 398.02732 | MQ3: 391.56343 | MR3: 352.01615 | MS3: 296.43521 | MT3: 388.82892 | MU3: 406.87074 | MV3: 392.31357 | MW3: 381.92121 | MX3: 375.62098 | MY3: 337.5948 | MZ3: 284.21497 | NA3: 392.31479 | NB3: 370.39139
A4: 332.5391 | B4: 350.88699 | C4: 341.18112 | D4: 334.95056 | E4: 332.22069 | F4: 301.13229 | G4: 255.68683 | H4: 338.16981 | I4: 356.81613 | J4: 346.93441 | K4: 340.58721 | L4: 337.79996 | M4: 306.17915 | N4: 259.96332 | O4: 343.81438 | P4: 362.75987 | Q4: 352.70186 | R4: 346.23772 | S4: 343.39296 | T4: 311.23842 | U4: 264.25032 | V4: 349.47281 | W4: 368.7182 | X4: 358.48347 | Y4: 351.9021 | Z4: 348.99967 | AA4: 316.31009 | AB4: 268.54783 | AC4: 355.14512 | AD4: 374.69113 | AE4: 364.27923 | AF4: 357.58035 | AG4: 353.09633 | AH4: 318.63789 | AI4: 269.35308 | AJ4: 354.66784 | AK4: 372.56732 | AL4: 360.64576 | AM4: 352.48028 | AN4: 348.04785 | AO4: 314.07088 | AP4: 265.48295 | AQ4: 349.5593 | AR4: 367.18768 | AS4: 355.42535 | AT4: 347.36539 | AU4: 342.98471 | AV4: 309.49061 | AW4: 261.60158 | AX4: 344.43594 | AY4: 361.79244 | AZ4: 350.18981 | BA4: 342.23568 | BB4: 337.9069 | BC4: 304.89708 | BD4: 257.70899 | BE4: 339.29776 | BF4: 356.3816 | BG4: 344.93913 | BH4: 337.09114 | BI4: 332.81442 | BJ4: 301.00611 | BK4: 255.01809 | BL4: 336.5458 | BM4: 354.32568 | BN4: 343.76084 | BO4: 336.73659 | BP4: 333.25492 | BQ4: 301.40444 | BR4: 255.35549 | BS4: 336.99098 | BT4: 354.7943 | BU4: 344.21541 | BV4: 337.18178 | BW4: 333.69543 | BX4: 301.80277 | BY4: 255.6929 | BZ4: 337.43617 | CA4: 355.26292 | CB4: 344.66997 | CC4: 337.62697 | CD4: 334.13593 | CE4: 302.20109 | CF4: 256.0303 | CG4: 337.88136 | CH4: 355.73154 | CI4: 345.12453 | CJ4: 338.07216 | CK4: 334.57643 | CL4: 302.59942 | CM4: 256.36771 | CN4: 338.32655 | CO4: 357.83786 | CP4: 348.75683 | CQ4: 343.18655 | CR4: 341.17816 | CS4: 309.96321 | CT4: 263.78664 | CU4: 349.67474 | CV4: 369.78763 | CW4: 360.35228 | CX4: 354.54702 | CY4: 352.4231 | CZ4: 320.13517 | DA4: 272.40598 | DB4: 361.05158 | DC4: 381.76756 | DD4: 371.977 | DE4: 365.93614 | DF4: 363.69639 | DG4: 330.33276 | DH4: 281.04705 | DI4: 372.45708 | DJ4: 393.77766 | DK4: 383.63097 | DL4: 377.35392 | DM4: 374.99803 | DN4: 340.556 | DO4: 289.70983 | DP4: 383.89123 | DQ4: 405.81792 | DR4: 395.3142 | DS4: 390.264 | DT4: 389.22505 | DU4: 354.73508 | DV4: 302.83398 | DW4: 402.67775 | DX4: 427.14107 | DY4: 417.49966 | DZ4: 411.99995 | EA4: 410.74003 | EB4: 374.1972 | EC4: 319.32556 | ED4: 424.44539 | EE4: 450.06271 | EF4: 439.74174 | EG4: 433.79135 | EH4: 432.3099 | EI4: 393.70896 | EJ4: 335.85916 | EK4: 446.26849 | EL4: 473.04274 | EM4: 462.04045 | EN4: 455.63822 | EO4: 453.93464 | EP4: 413.27033 | EQ4: 352.4348 | ER4: 468.14705 | ES4: 496.08114 | ET4: 484.3958 | EU4: 477.54056 | EV4: 475.61426 | EW4: 432.88134 | EX4: 368.5331 | EY4: 488.71022 | EZ4: 517.01302 | FA4: 504.0073 | FB4: 496.0693 | FC4: 493.27646 | FD4: 448.24503 | FE4: 381.5517 | FF4: 505.89369 | FG4: 535.10735 | FH4: 521.56506 | FI4: 513.27119 | FJ4: 510.30335 | FK4: 463.64718 | FL4: 394.60289 | FM4: 523.12014 | FN4: 553.24692 | FO4: 539.16672 | FP4: 530.51606 | FQ4: 527.37278 | FR4: 479.0878 | FS4: 407.68665 | FT4: 540.38958 | FU4: 571.43174 | FV4: 556.81226 | FW4: 547.80392 | FX4: 544.48474 | FY4: 494.56687 | FZ4: 420.80299 | GA4: 557.702 | GB4: 586.76024 | GC4: 568.87163 | GD4: 556.86226 | GE4: 550.7233 | GF4: 497.74365 | GG4: 421.40558 | GH4: 555.74062 | GI4: 584.69459 | GJ4: 566.86694 | GK4: 554.89791 | GL4: 548.77866 | GM4: 495.9843 | GN4: 419.91456 | GO4: 553.77232 | GP4: 582.62165 | GQ4: 564.85517 | GR4: 552.92664 | GS4: 546.82715 | GT4: 494.21876 | GU4: 418.41828 | GV4: 551.79708 | GW4: 580.54141 | GX4: 562.83632 | GY4: 550.94843 | GZ4: 544.86878 | HA4: 492.44701 | HB4: 416.91676 | HC4: 549.81491 | HD4: 578.45387 | HE4: 560.8104 | HF4: 548.96328 | HG4: 543.28454 | HH4: 491.3582 | HI4: 416.28575 | HJ4: 549.3668 | HK4: 578.38703 | HL4: 561.13843 | HM4: 549.66944 | HN4: 543.98327 | HO4: 491.99002 | HP4: 416.82095 | HQ4: 550.07296 | HR4: 579.13036 | HS4: 561.85946 | HT4: 550.3756 | HU4: 544.682 | HV4: 492.62185 | HW4: 417.35614 | HX4: 550.77912 | HY4: 579.87369 | HZ4: 562.58048 | IA4: 551.08177 | IB4: 545.38072 | IC4: 493.25368 | ID4: 417.89134 | IE4: 551.48529 | IF4: 580.61702 | IG4: 563.30151 | IH4: 551.78793 | II4: 546.07945 | IJ4: 493.88551 | IK4: 418.42653 | IL4: 550.59089 | IM4: 577.99014 | IN4: 559.11799 | IO4: 546.08836 | IP4: 538.85386 | IQ4: 485.91704 | IR4: 410.46106 | IS4: 540.07679 | IT4: 566.91836 | IU4: 548.37419 | IV4: 535.56198 | IW4: 528.43423 | IX4: 476.49137 | IY4: 402.47386 | IZ4: 529.53404 | JA4: 555.81641 | JB4: 537.60112 | JC4: 525.00694 | JD4: 517.98625 | JE4: 467.04007 | JF4: 394.46495 | JG4: 518.96263 | JH4: 544.6843 | JI4: 526.79879 | JJ4: 514.42325 | JK4: 507.50992 | JL4: 457.56312 | JM4: 386.43432 | JN4: 508.36256 | JO4: 533.52203 | JP4: 514.43002 | JQ4: 500.79936 | JR4: 492.53465 | JS4: 442.6695 | JT4: 372.67277 | JU4: 488.69264 | JV4: 511.22435 | JW4: 492.79317 | JX4: 479.60071 | JY4: 471.5513 | JZ4: 423.68811 | KA4: 356.58841 | KB4: 467.4623 | KC4: 488.86828 | KD4: 471.0997 | KE4: 458.3466 | KF4: 450.51308 | KG4: 404.6571 | KH4: 340.46202 | KI4: 446.1765 | KJ4: 466.45383 | KK4: 449.34959 | KL4: 437.03703 | KM4: 429.41998 | KN4: 385.57646 | KO4: 324.29359 | KP4: 424.83523 | KQ4: 443.981 | KR4: 427.54285 | KS4: 415.67199 | KT4: 408.272 | KU4: 369.97286 | KV4: 314.05879 | KW4: 415.26747 | KX4: 438.05485 | KY4: 425.81677 | KZ4: 417.92226 | LA4: 414.39927 | LB4: 375.51531 | LC4: 318.75513 | LD4: 421.46607 | LE4: 444.58185 | LF4: 432.15004 | LG4: 424.127 | LH4: 420.54072 | LI4: 381.07058 | LJ4: 323.46232 | LK4: 427.679 | LL4: 451.12392 | LM4: 438.49794 | LN4: 430.34606 | LO4: 426.69635 | LP4: 386.63867 | LQ4: 328.18037 | LR4: 433.90625 | LS4: 457.68108 | LT4: 444.86048 | LU4: 436.57946 | LV4: 432.86615 | LW4: 392.21958 | LX4: 332.90928 | LY4: 436.57857 | LZ4: 456.73773 | MA4: 440.30049 | MB4: 428.54243 | MC4: 421.37898 | MD4: 378.63479 | ME4: 318.69275 | MF4: 417.81372 | MG4: 436.97796 | MH4: 421.12644 | MI4: 409.75678 | MJ4: 402.78422 | MK4: 361.81417 | ML4: 304.43945 | MM4: 399.00034 | MN4: 417.16711 | MO4: 401.90283 | MP4: 390.92261 | MQ4: 384.14144 | MR4: 344.95013 | MS4: 290.14936 | MT4: 380.13843 | MU4: 397.30517 | MV4: 382.62967 | MW4: 372.0399 | MX4: 365.45063 | MY4: 328.04267 | MZ4: 275.82249 | NA4: 380.23999 | NB4: 358.52254
A5: 344.00871 | B5: 362.57313 | C5: 352.14102 | D5: 345.31642 | E5: 342.11311 | F5: 309.748 | G5: 262.70558 | H5: 347.06203 | I5: 365.78819 | J5: 355.26064 | K5: 348.37271 | L5: 345.13821 | M5: 312.48435 | N5: 265.02417 | O5: 350.12228 | P5: 369.01055 | Q5: 358.38734 | R5: 351.43594 | S5: 348.17017 | T5: 315.2269 | U5: 267.34803 | V5: 353.18946 | W5: 372.24021 | X5: 361.52112 | Y5: 354.50609 | Z5: 351.20899 | AA5: 317.97565 | AB5: 269.67713 | AC5: 356.26358 | AD5: 375.47716 | AE5: 364.66198 | AF5: 357.58318 | AG5: 353.49277 | AH5: 319.35246 | AI5: 270.2601 | AJ5: 356.26288 | AK5: 374.66572 | AL5: 363.08818 | AM5: 355.27107 | AN5: 351.20395 | AO5: 317.28183 | AP5: 268.50535 | AQ5: 353.94654 | AR5: 372.22634 | AS5: 360.72091 | AT5: 352.95155 | AU5: 348.9078 | AV5: 315.20458 | AW5: 266.74499 | AX5: 351.62278 | AY5: 369.77917 | AZ5: 358.34607 | BA5: 350.62462 | BB5: 346.60431 | BC5: 313.12069 | BD5: 264.97902 | BE5: 349.29161 | BF5: 367.32419 | BG5: 355.96366 | BH5: 348.29027 | BI5: 344.29349 | BJ5: 311.05326 | BK5: 263.24655 | BL5: 347.03049 | BM5: 364.97015 | BN5: 353.70554 | BO5: 346.10351 | BP5: 342.1543 | BQ5: 309.118 | BR5: 261.60652 | BS5: 344.86557 | BT5: 362.69024 | BU5: 351.49302 | BV5: 343.93562 | BW5: 340.00824 | BX5: 307.17653 | BY5: 259.96123 | BZ5: 342.69371 | CA5: 360.40303 | CB5: 349.27342 | CC5: 341.76079 | CD5: 337.85533 | CE5: 305.22886 | CF5: 258.31069 | CG5: 340.51492 | CH5: 358.10853 | CI5: 347.04674 | CJ5: 339.57903 | CK5: 335.69556 | CL5: 303.27499 | CM5: 256.65489 | CN5: 338.3292 | CO5: 357.84066 | CP5: 348.75956 | CQ5: 343.18924 | CR5: 341.18083 | CS5: 309.96564 | CT5: 263.7887 | CU5: 349.67747 | CV5: 369.79052 | CW5: 360.3551 | CX5: 354.54979 | CY5: 352.42585 | CZ5: 320.13767 | DA5: 272.40811 | DB5: 361.0544 | DC5: 381.77054 | DD5: 371.9799 | DE5: 365.939 | DF5: 363.69923 | DG5: 330.33534 | DH5: 281.04924 | DI5: 372.45998 | DJ5: 393.78073 | DK5: 383.63396 | DL5: 377.35686 | DM5: 375.00095 | DN5: 340.55865 | DO5: 289.71209 | DP5: 383.89422 | DQ5: 405.82108 | DR5: 395.31728 | DS5: 389.50998 | DT5: 387.72961 | DU5: 352.70496 | DV5: 300.53995 | DW5: 398.89273 | DX5: 422.35846 | DY5: 412.08581 | DZ5: 405.93871 | EA5: 403.99128 | EB5: 367.41498 | EC5: 313.00471 | ED5: 415.34523 | EE5: 439.68314 | EF5: 428.89682 | EG5: 422.40903 | EH5: 420.29412 | EI5: 382.16222 | EJ5: 325.501 | EK5: 431.83933 | EL5: 457.0516 | EM5: 445.75029 | EN5: 438.92096 | EO5: 436.63811 | EP5: 396.94668 | EQ5: 338.02881 | ER5: 448.37502 | ES5: 474.46385 | ET5: 462.64624 | EU5: 455.47448 | EV5: 453.02327 | EW5: 411.76836 | EX5: 350.94402 | EY5: 465.89161 | EZ5: 493.40326 | FA5: 481.50352 | FB5: 474.41915 | FC5: 472.23988 | FD5: 429.57148 | FE5: 366.02974 | FF5: 485.80354 | FG5: 514.37073 | FH5: 501.84928 | FI5: 494.35257 | FJ5: 491.97057 | FK5: 447.41946 | FL5: 381.15346 | FM5: 505.76561 | FN5: 535.39098 | FO5: 522.24623 | FP5: 514.33614 | FQ5: 511.75087 | FR5: 465.31231 | FS5: 396.31519 | FT5: 525.77783 | FU5: 556.46402 | FV5: 542.6944 | FW5: 534.36985 | FX5: 531.58079 | FY5: 483.25003 | FZ5: 411.51492 | GA5: 545.8402 | GB5: 574.27183 | GC5: 556.75562 | GD5: 544.99387 | GE5: 538.97768 | GF5: 487.12064 | GG5: 412.4056 | GH5: 543.86346 | GI5: 572.19 | GJ5: 554.73524 | GK5: 543.01416 | GL5: 537.01782 | GM5: 485.34754 | GN5: 410.90293 | GO5: 541.87978 | GP5: 570.10087 | GQ5: 552.70778 | GR5: 541.02751 | GS5: 535.0511 | GT5: 483.56824 | GU5: 409.395 | GV5: 539.88917 | GW5: 568.00445 | GX5: 550.67323 | GY5: 539.03393 | GZ5: 533.07752 | HA5: 481.78274 | HB5: 407.88183 | HC5: 537.89162 | HD5: 565.90073 | HE5: 548.63161 | HF5: 537.03341 | HG5: 531.85906 | HH5: 481.36932 | HI5: 408.11496 | HJ5: 538.96917 | HK5: 567.84575 | HL5: 551.30501 | HM5: 540.42248 | HN5: 535.21344 | HO5: 484.40342 | HP5: 410.68577 | HQ5: 542.3622 | HR5: 571.4184 | HS5: 554.7715 | HT5: 543.81848 | HU5: 538.57467 | HV5: 487.44372 | HW5: 413.26183 | HX5: 545.76216 | HY5: 574.99835 | HZ5: 558.24506 | IA5: 547.22141 | IB5: 541.94276 | IC5: 490.49022 | ID5: 415.84315 | IE5: 549.16906 | IF5: 578.5856 | IG5: 561.7257 | IH5: 550.63128 | II5: 545.31771 | IJ5: 493.54292 | IK5: 418.42972 | IL5: 550.59508 | IM5: 577.99454 | IN5: 559.12225 | IO5: 546.09251 | IP5: 538.85796 | IQ5: 485.92073 | IR5: 410.46418 | IS5: 540.0809 | IT5: 566.92267 | IU5: 548.37835 | IV5: 535.56605 | IW5: 528.43825 | IX5: 476.49499 | IY5: 402.47692 | IZ5: 529.53806 | JA5: 555.82063 | JB5: 537.6052 | JC5: 525.01093 | JD5: 517.99018 | JE5: 467.04361 | JF5: 394.46794 | JG5: 518.96657 | JH5: 544.68843 | JI5: 526.80279 | JJ5: 514.42715 | JK5: 507.51376 | JL5: 457.56659 | JM5: 386.43724 | JN5: 508.36641 | JO5: 533.52607 | JP5: 514.43391 | JQ5: 500.80315 | JR5: 492.53838 | JS5: 442.67285 | JT5: 372.67559 | JU5: 488.69634 | JV5: 511.22821 | JW5: 492.7969 | JX5: 479.60434 | JY5: 471.55487 | JZ5: 423.69131 | KA5: 356.59111 | KB5: 467.46583 | KC5: 488.87197 | KD5: 471.10325 | KE5: 458.35006 | KF5: 450.51648 | KG5: 404.66015 | KH5: 340.46459 | KI5: 446.17986 | KJ5: 466.45735 | KK5: 449.35298 | KL5: 437.04033 | KM5: 429.42322 | KN5: 385.57936 | KO5: 324.29604 | KP5: 424.83843 | KQ5: 443.98434 | KR5: 427.54608 | KS5: 415.67512 | KT5: 408.27507 | KU5: 369.97564 | KV5: 314.06116 | KW5: 415.2706 | KX5: 438.05815 | KY5: 425.81997 | KZ5: 417.9254 | LA5: 414.40239 | LB5: 375.51813 | LC5: 318.75752 | LD5: 421.46924 | LE5: 444.58519 | LF5: 432.15329 | LG5: 424.13019 | LH5: 420.54388 | LI5: 381.07344 | LJ5: 323.46475 | LK5: 427.68221 | LL5: 451.12731 | LM5: 438.50123 | LN5: 430.34929 | LO5: 426.69955 | LP5: 386.64157 | LQ5: 328.18283 | LR5: 433.9095 | LS5: 457.68451 | LT5: 444.86381 | LU5: 436.58273 | LV5: 432.8694 | LW5: 392.22252 | LX5: 332.91177 | LY5: 436.97551 | LZ5: 457.57008 | MA5: 441.5101 | MB5: 430.12117 | MC5: 423.33118 | MD5: 380.75291 | ME5: 320.78592 | MF5: 420.97018 | MG5: 440.71611 | MH5: 425.15568 | MI5: 414.09802 | MJ5: 407.4708 | MK5: 366.40577 | ML5: 308.62854 | MM5: 404.92325 | MN5: 423.81835 | MO5: 408.75879 | MP5: 398.03326 | MQ5: 391.56927 | MR5: 352.02141 | MS5: 296.43964 | MT5: 388.83473 | MU5: 406.87681 | MV5: 392.31942 | MW5: 381.92691 | MX5: 375.62658 | MY5: 337.59983 | MZ5: 284.21921 | NA5: 392.32063 | NB5: 370.3969
A6: 344.01145 | B6: 362.96546 | C6: 352.89949 | D6: 346.42952 | E6: 343.581 | F6: 311.40689 | G6: 264.39169 | H6: 349.65759 | I6: 368.91085 | J6: 358.66854 | K6: 352.08161 | L6: 349.17554 | M6: 316.46756 | N6: 268.67988 | O6: 355.31759 | P6: 374.87084 | Q6: 364.45175 | R6: 357.74755 | S6: 354.78381 | T6: 321.54063 | U6: 272.97857 | V6: 360.99146 | W6: 380.84542 | X6: 370.24912 | Y6: 363.42737 | Z6: 360.4058 | AA6: 326.62612 | AB6: 277.28778 | AC6: 366.6792 | AD6: 386.8346 | AE6: 376.06064 | AF6: 369.12105 | AG6: 364.91135 | AH6: 329.67973 | AI6: 279.00956 | AJ6: 367.80951 | AK6: 386.82236 | AL6: 374.88236 | AM6: 366.82427 | AN6: 362.6377 | AO6: 327.62282 | AP6: 277.26644 | AQ6: 365.50849 | AR6: 384.39913 | AS6: 372.53074 | AT6: 364.52007 | AU6: 360.35672 | AV6: 325.55928 | AW6: 275.5177 | AX6: 363.20006 | AY6: 381.96809 | AZ6: 370.17156 | BA6: 362.20847 | BB6: 358.0684 | BC6: 323.48911 | BD6: 273.76334 | BE6: 360.88423 | BF6: 379.52925 | BG6: 367.8048 | BH6: 359.88946 | BI6: 355.77275 | BJ6: 321.4354 | BK6: 272.04249 | BL6: 358.63843 | BM6: 377.19134 | BN6: 365.56234 | BO6: 357.71803 | BP6: 353.64872 | BQ6: 319.51385 | BR6: 270.41407 | BS6: 356.48884 | BT6: 374.92757 | BU6: 363.36547 | BV6: 355.56546 | BW6: 351.51784 | BX6: 317.5861 | BY6: 268.78041 | BZ6: 354.33231 | CA6: 372.6565 | CB6: 361.16152 | CC6: 353.40597 | CD6: 349.38009 | CE6: 315.65215 | CF6: 267.14148 | CG6: 352.16886 | CH6: 370.37813 | CI6: 358.95049 | CJ6: 351.23954 | CK6: 347.23549 | CL6: 313.71199 | CM6: 265.49731 | CN6: 349.99846 | CO6: 369.71699 | CP6: 359.88455 | CQ6: 353.6978 | CR6: 351.19566 | CS6: 318.67503 | CT6: 270.8724 | CU6: 358.63638 | CV6: 378.81276 | CW6: 368.71058 | CX6: 362.34492 | CY6: 359.7548 | CZ6: 326.41743 | DA6: 277.43299 | DB6: 367.29579 | DC6: 387.93116 | DD6: 377.55857 | DE6: 371.01354 | DF6: 368.33521 | DG6: 334.17906 | DH6: 284.00987 | DI6: 375.97669 | DJ6: 397.07218 | DK6: 386.42849 | DL6: 379.70365 | DM6: 376.93689 | DN6: 341.95991 | DO6: 290.60304 | DP6: 384.67908 | DQ6: 406.23583 | DR6: 395.32036 | DS6: 389.51301 | DT6: 387.73263 | DU6: 352.7077 | DV6: 300.54229 | DW6: 398.89583 | DX6: 422.36175 | DY6: 412.08902 | DZ6: 405.94186 | EA6: 403.99443 | EB6: 367.41784 | EC6: 313.00714 | ED6: 415.34846 | EE6: 439.68656 | EF6: 428.90015 | EG6: 422.41232 | EH6: 420.29738 | EI6: 382.16519 | EJ6: 325.50352 | EK6: 431.84268 | EL6: 457.05515 | EM6: 445.75375 | EN6: 438.92436 | EO6: 436.6415 | EP6: 396.94976 | EQ6: 338.03143 | ER6: 448.3785 | ES6: 474.46753 | ET6: 462.64983 | EU6: 455.47801 | EV6: 453.02678 | EW6: 411.77155 | EX6: 350.94674 | EY6: 465.89522 | EZ6: 493.40708 | FA6: 481.50725 | FB6: 474.42282 | FC6: 472.24354 | FD6: 429.5748 | FE6: 366.03257 | FF6: 485.80729 | FG6: 514.3747 | FH6: 501.85315 | FI6: 494.35639 | FJ6: 491.97437 | FK6: 447.42292 | FL6: 381.1564 | FM6: 505.76951 | FN6: 535.39511 | FO6: 522.25026 | FP6: 514.3401 | FQ6: 511.75481 | FR6: 465.3159 | FS6: 396.31824 | FT6: 525.78189 | FU6: 556.46831 | FV6: 542.69858 | FW6: 534.37397 | FX6: 531.58488 | FY6: 483.25376 | FZ6: 411.51809 | GA6: 545.8444 | GB6: 574.27625 | GC6: 556.75991 | GD6: 544.99807 | GE6: 538.98182 | GF6: 487.12439 | GG6: 412.40877 | GH6: 543.86764 | GI6: 572.1944 | GJ6: 554.7395 | GK6: 543.01833 | GL6: 537.02195 | GM6: 485.35127 | GN6: 410.90608 | GO6: 541.88394 | GP6: 570.10525 | GQ6: 552.71202 | GR6: 541.03166 | GS6: 535.05521 | GT6: 483.57195 | GU6: 409.39815 | GV6: 539.89331 | GW6: 568.00881 | GX6: 550.67746 | GY6: 539.03806 | GZ6: 533.08161 | HA6: 481.78643 | HB6: 407.88495 | HC6: 537.89574 | HD6: 565.90506 | HE6: 548.63582 | HF6: 537.03752 | HG6: 531.48214 | HH6: 480.68385 | HI6: 407.24229 | HJ6: 537.43227 | HK6: 565.82206 | HL6: 548.94816 | HM6: 537.72833 | HN6: 532.16568 | HO6: 481.30195 | HP6: 407.76586 | HQ6: 538.12308 | HR6: 566.54923 | HS6: 549.65352 | HT6: 538.41914 | HU6: 532.84922 | HV6: 481.92004 | HW6: 408.28942 | HX6: 538.81389 | HY6: 567.2764 | HZ6: 550.35887 | IA6: 539.10995 | IB6: 533.53276 | IC6: 482.53813 | ID6: 408.81298 | IE6: 539.5047 | IF6: 568.00356 | IG6: 551.06422 | IH6: 539.80076 | II6: 534.2163 | IJ6: 483.15623 | IK6: 409.33654 | IL6: 539.39522 | IM6: 567.0456 | IN6: 549.31727 | IO6: 537.28866 | IP6: 530.93761 | IQ6: 479.4741 | IR6: 405.6097 | IS6: 534.47581 | IT6: 561.86513 | IU6: 544.29011 | IV6: 532.36311 | IW6: 526.06189 | IX6: 475.06337 | IY6: 401.872 | IZ6: 529.54208 | JA6: 556.66957 | JB6: 539.24833 | JC6: 527.42324 | JD6: 521.17199 | JE6: 470.63982 | JF6: 398.12344 | JG6: 524.59402 | JH6: 551.45893 | JI6: 534.19192 | JJ6: 522.46904 | JK6: 516.26791 | JL6: 466.20345 | JM6: 394.36402 | JN6: 519.63163 | JO6: 546.23321 | JP6: 527.55716 | JQ6: 514.43699 | JR6: 506.80193 | JS6: 456.27019 | JT6: 384.78603 | JU6: 505.45769 | JV6: 529.69552 | JW6: 511.50953 | JX6: 498.7143 | JY6: 491.23886 | JZ6: 442.19189 | KA6: 372.85637 | KB6: 489.71123 | KC6: 513.11404 | KD6: 495.41943 | KE6: 482.95001 | KF6: 475.63463 | KG6: 428.07636 | KH6: 360.89519 | KI6: 473.92317 | KJ6: 496.48877 | KK6: 479.28685 | KL6: 467.14412 | KM6: 459.98924 | KN6: 413.92362 | KO6: 348.90248 | KP6: 458.09351 | KQ6: 479.81972 | KR6: 463.11181 | KS6: 451.29664 | KT6: 444.30269 | KU6: 401.47366 | KV6: 339.82654 | KW6: 448.05849 | KX6: 471.29957 | KY6: 456.82972 | KZ6: 447.08635 | LA6: 442.05926 | LB6: 399.44411 | LC6: 338.10662 | LD6: 445.78812 | LE6: 468.90863 | LF6: 454.50946 | LG6: 444.81291 | LH6: 439.80874 | LI6: 397.40814 | LJ6: 336.38126 | LK6: 443.51059 | LL6: 466.51015 | LM6: 452.18189 | LN6: 442.53231 | LO6: 437.55113 | LP6: 395.36577 | LQ6: 334.65048 | LR6: 441.22589 | LS6: 464.10413 | LT6: 449.847 | LU6: 440.24454 | LV6: 435.28643 | LW6: 393.31699 | LX6: 332.91427 | LY6: 436.97878 | LZ6: 457.57351 | MA6: 441.51341 | MB6: 430.12439 | MC6: 423.33434 | MD6: 380.75576 | ME6: 320.78832 | MF6: 420.97333 | MG6: 440.71941 | MH6: 425.15886 | MI6: 414.10111 | MJ6: 407.47385 | MK6: 366.40851 | ML6: 308.63085 | MM6: 404.92627 | MN6: 423.82152 | MO6: 408.76184 | MP6: 398.03623 | MQ6: 391.57219 | MR6: 352.02403 | MS6: 296.44185 | MT6: 388.83763 | MU6: 406.87984 | MV6: 392.32235 | MW6: 381.92976 | MX6: 375.62938 | MY6: 337.60234 | MZ6: 284.22132 | NA6: 392.32356 | NB6: 370.39966
A7: 412.81703 | B7: 434.62734 | C7: 421.66914 | D7: 413.05388 | E7: 408.78406 | F7: 369.7158 | G7: 313.23087 | H7: 413.36967 | I7: 435.20908 | J7: 422.23342 | K7: 413.60652 | L7: 409.33089 | M7: 370.21027 | N7: 313.64971 | O7: 413.92232 | P7: 435.79081 | Q7: 422.7977 | R7: 414.15917 | S7: 409.87772 | T7: 370.70475 | U7: 314.06856 | V7: 414.47497 | W7: 436.37255 | X7: 423.36198 | Y7: 414.71182 | Z7: 410.42455 | AA7: 371.19922 | AB7: 314.48741 | AC7: 415.02762 | AD7: 436.95428 | AE7: 423.92626 | AF7: 415.26447 | AG7: 410.97138 | AH7: 371.6937 | AI7: 314.90626 | AJ7: 415.58027 | AK7: 437.53602 | AL7: 424.49055 | AM7: 415.81711 | AN7: 411.51821 | AO7: 372.18817 | AP7: 315.32511 | AQ7: 416.13291 | AR7: 438.11775 | AS7: 425.05483 | AT7: 416.36976 | AU7: 412.06504 | AV7: 372.68264 | AW7: 315.74396 | AX7: 416.68556 | AY7: 438.69948 | AZ7: 425.61911 | BA7: 416.92241 | BB7: 412.61187 | BC7: 373.17712 | BD7: 316.16281 | BE7: 417.23821 | BF7: 439.28122 | BG7: 426.18339 | BH7: 417.47506 | BI7: 413.1587 | BJ7: 373.00193 | BK7: 315.44695 | BL7: 415.54467 | BM7: 436.70981 | BN7: 422.92377 | BO7: 413.53278 | BP7: 408.51568 | BQ7: 368.80168 | BR7: 311.88759 | BS7: 410.84631 | BT7: 431.76209 | BU7: 418.12245 | BV7: 408.82848 | BW7: 403.85893 | BX7: 364.58902 | BY7: 308.31772 | BZ7: 406.13408 | CA7: 426.79976 | CB7: 413.30698 | CC7: 404.11031 | CD7: 399.18847 | CE7: 360.36396 | CF7: 304.73734 | CG7: 401.40799 | CH7: 421.82285 | CI7: 408.47735 | CJ7: 399.37828 | CK7: 394.50429 | CL7: 356.12649 | CM7: 301.14646 | CN7: 396.66803 | CO7: 418.03322 | CP7: 405.96566 | CQ7: 398.05905 | CR7: 394.32804 | CS7: 356.98848 | CT7: 302.7421 | CU7: 399.91579 | CV7: 421.45299 | CW7: 409.28388 | CX7: 401.30988 | CY7: 397.54566 | CZ7: 359.89895 | DA7: 305.20822 | DB7: 403.17071 | DC7: 424.8803 | DD7: 412.60942 | DE7: 404.56787 | DF7: 400.77037 | DG7: 362.81583 | DH7: 307.67976 | DI7: 406.4328 | DJ7: 428.31516 | DK7: 415.94227 | DL7: 407.83303 | DM7: 404.00217 | DN7: 365.73912 | DO7: 310.15673 | DP7: 409.70205 | DQ7: 431.75755 | DR7: 419.28244 | DS7: 412.60689 | DT7: 410.21308 | DU7: 372.70076 | DV7: 317.19371 | DW7: 420.49176 | DX7: 444.69973 | DY7: 433.37398 | DZ7: 426.41284 | EA7: 423.8786 | EB7: 385.06231 | EC7: 327.66843 | ED7: 434.31751 | EE7: 459.25837 | EF7: 447.50092 | EG7: 440.25345 | EH7: 437.57842 | EI7: 397.45488 | EJ7: 338.16941 | EK7: 448.17794 | EL7: 473.8535 | EM7: 461.66325 | EN7: 454.12873 | EO7: 451.31254 | EP7: 409.87847 | EQ7: 348.69667 | ER7: 462.07302 | ES7: 488.48512 | ET7: 475.86098 | EU7: 468.03867 | EV7: 465.08097 | EW7: 422.33307 | EX7: 359.2983 | EY7: 476.12971 | EZ7: 503.35369 | FA7: 490.35341 | FB7: 482.30079 | FC7: 479.26076 | FD7: 435.21655 | FE7: 370.21525 | FF7: 490.53913 | FG7: 518.52689 | FH7: 505.07664 | FI7: 496.72557 | FJ7: 493.53876 | FK7: 448.13209 | FL7: 381.15935 | FM7: 504.98438 | FN7: 533.7378 | FO7: 519.83645 | FP7: 511.18617 | FQ7: 507.85221 | FR7: 461.07968 | FS7: 392.13059 | FT7: 519.46545 | FU7: 548.98642 | FV7: 534.63283 | FW7: 525.68258 | FX7: 522.20109 | FY7: 474.05931 | FZ7: 403.12899 | GA7: 533.98233 | GB7: 561.78754 | GC7: 544.64362 | GD7: 533.12941 | GE7: 527.23593 | GF7: 476.50113 | GG7: 403.40858 | GH7: 531.9902 | GI7: 559.68951 | GJ7: 542.60752 | GK7: 531.1343 | GL7: 525.26084 | GM7: 474.71426 | GN7: 401.89425 | GO7: 529.99113 | GP7: 557.58419 | GQ7: 540.56435 | GR7: 529.13226 | GS7: 523.27889 | GT7: 472.92119 | GU7: 400.37466 | GV7: 527.98512 | GW7: 555.47156 | GX7: 538.51409 | GY7: 527.12328 | GZ7: 521.29008 | HA7: 471.12191 | HB7: 398.84981 | HC7: 525.97218 | HD7: 553.35164 | HE7: 536.45675 | HF7: 525.10738 | HG7: 520.0564 | HH7: 470.69475 | HI7: 399.07131 | HJ7: 527.03439 | HK7: 555.28052 | HL7: 539.11451 | HM7: 528.48113 | HN7: 523.39563 | HO7: 473.71514 | HP7: 401.63051 | HQ7: 530.41211 | HR7: 558.83706 | HS7: 542.56536 | HT7: 531.86182 | HU7: 526.74171 | HV7: 476.74174 | HW7: 404.19497 | HX7: 533.79676 | HY7: 562.40089 | HZ7: 546.02329 | IA7: 535.24945 | IB7: 530.09465 | IC7: 479.77455 | ID7: 406.76469 | IE7: 537.18834 | IF7: 565.97202 | IG7: 549.4883 | IH7: 538.644 | II7: 533.45446 | IJ7: 482.81355 | IK7: 409.33966 | IL7: 539.79947 | IM7: 567.89249 | IN7: 550.54761 | IO7: 538.89421 | IP7: 532.92278 | IQ7: 481.62787 | IR7: 407.738 | IS7: 537.68515 | IT7: 565.66581 | IU7: 548.38669 | IV7: 536.77682 | IW7: 530.82666 | IX7: 479.73154 | IY7: 406.13091 | IZ7: 535.56367 | JA7: 563.4316 | JB7: 546.21845 | JC7: 534.65227 | JD7: 528.72346 | JE7: 477.82879 | JF7: 404.5184 | JG7: 533.43502 | JH7: 561.18984 | JI7: 544.0429 | JJ7: 532.52055 | JK7: 526.61317 | JL7: 475.91963 | JM7: 402.90046 | JN7: 531.29921 | JO7: 558.94054 | JP7: 541.47573 | JQ7: 529.62877 | JR7: 523.37812 | JS7: 472.65627 | JT7: 399.84975 | JU7: 526.89589 | JV7: 553.90732 | JW7: 536.59149 | JX7: 524.84325 | JY7: 518.64102 | JZ7: 468.37095 | KA7: 396.21833 | KB7: 522.10245 | KC7: 548.85951 | KD7: 531.69309 | KE7: 520.04387 | KF7: 513.8902 | KG7: 464.07322 | KH7: 392.5764 | KI7: 517.29514 | KJ7: 543.79711 | KK7: 526.78053 | KL7: 515.23062 | KM7: 509.12565 | KN7: 459.76309 | KO7: 388.92396 | KP7: 512.47397 | KQ7: 538.7201 | KR7: 521.85382 | KS7: 510.40351 | KT7: 504.34739 | KU7: 456.14122 | KV7: 386.44826 | KW7: 509.98911 | KX7: 536.9276 | KY7: 520.91382 | KZ7: 510.26544 | LA7: 504.98536 | LB7: 456.71811 | LC7: 386.93691 | LD7: 510.63387 | LE7: 537.60629 | LF7: 521.57215 | LG7: 510.91019 | LH7: 505.62333 | LI7: 457.295 | LJ7: 387.42557 | LK7: 511.27862 | LL7: 538.28498 | LM7: 522.23048 | LN7: 511.55495 | LO7: 506.2613 | LP7: 457.87188 | LQ7: 387.91423 | LR7: 511.92338 | LS7: 538.96367 | LT7: 522.88881 | LU7: 512.1997 | LV7: 506.89927 | LW7: 458.44877 | LX7: 388.40288 | LY7: 510.20607 | LZ7: 534.6687 | MA7: 516.30916 | MB7: 503.39111 | MC7: 495.84283 | MD7: 446.3337 | ME7: 376.34665 | MF7: 494.2926 | MG7: 517.91142 | MH7: 500.04853 | MI7: 487.45981 | MJ7: 480.07335 | MK7: 432.06875 | ML7: 364.2589 | MM7: 478.33753 | MN7: 501.11036 | MO7: 483.74544 | MP7: 471.48691 | MQ7: 464.26271 | MR7: 417.76658 | MS7: 352.13961 | MT7: 462.34087 | MU7: 484.26551 | MV7: 467.39986 | MW7: 455.47242 | MX7: 448.41091 | MY7: 403.42719 | MZ7: 339.9888 | NA7: 469.79222 | NB7: 444.00803
A8: 561.89432 | B8: 590.80191 | C8: 572.43175 | D8: 559.99596 | E8: 553.47458 | F8: 499.9154 | G8: 422.9773 | H8: 557.46085 | I8: 586.13302 | J8: 567.9009 | K8: 555.55655 | L8: 549.07994 | M8: 495.93975 | N8: 419.60819 | O8: 553.01352 | P8: 581.44953 | Q8: 563.35589 | R8: 551.10327 | S8: 544.67158 | T8: 491.95169 | U8: 416.22858 | V8: 548.55232 | W8: 576.75145 | X8: 558.79673 | Y8: 546.63613 | Z8: 540.2495 | AA8: 487.95123 | AB8: 412.83845 | AC8: 544.07726 | AD8: 572.03877 | AE8: 554.22341 | AF8: 542.15513 | AG8: 535.36926 | AH8: 483.13442 | AI8: 408.41614 | AJ8: 537.7906 | AK8: 564.94561 | AL8: 546.88152 | AM8: 534.51244 | AN8: 527.80387 | AO8: 476.29054 | AP8: 402.61657 | AQ8: 530.1352 | AR8: 556.88396 | AS8: 539.05847 | AT8: 526.84751 | AU8: 520.21649 | AV8: 469.42677 | AW8: 396.80014 | AX8: 522.45757 | AY8: 548.7989 | AZ8: 531.21272 | BA8: 519.16035 | BB8: 512.60711 | BC8: 462.5431 | BD8: 390.96686 | BE8: 514.75771 | BF8: 540.69044 | BG8: 523.34427 | BH8: 511.45096 | BI8: 504.97573 | BJ8: 456.04365 | BK8: 385.80147 | BL8: 508.39108 | BM8: 534.46134 | BN8: 517.76067 | BO8: 506.43181 | BP8: 500.45418 | BQ8: 451.95325 | BR8: 382.33516 | BS8: 503.81549 | BT8: 529.64285 | BU8: 513.0847 | BV8: 501.85028 | BW8: 495.91891 | BX8: 447.85044 | BY8: 378.85833 | BZ8: 499.22604 | CA8: 524.80976 | CB8: 508.39458 | CC8: 497.25488 | CD8: 491.36992 | CE8: 443.73522 | CF8: 375.371 | CG8: 494.62271 | CH8: 519.96207 | CI8: 503.6903 | CJ8: 492.64562 | CK8: 486.80722 | CL8: 439.6076 | CM8: 371.87316 | CN8: 490.00553 | CO8: 517.12056 | CP8: 502.8929 | CQ8: 493.78386 | CR8: 489.83319 | CS8: 444.06232 | CT8: 377.10276 | CU8: 498.82779 | CV8: 526.41038 | CW8: 511.90717 | CX8: 502.61533 | CY8: 498.57474 | CZ8: 451.96966 | DA8: 383.80307 | DB8: 507.67154 | DC8: 535.72283 | DD8: 520.94337 | DE8: 511.4683 | DF8: 507.33755 | DG8: 459.89622 | DH8: 390.51967 | DI8: 516.53678 | DJ8: 545.0579 | DK8: 530.00152 | DL8: 520.34275 | DM8: 516.12163 | DN8: 467.84202 | DO8: 397.25255 | DP8: 525.42352 | DQ8: 554.41559 | DR8: 539.08162 | DS8: 530.33647 | DT8: 527.09981 | DU8: 478.75479 | DV8: 407.33156 | DW8: 539.8247 | DX8: 570.73566 | DY8: 556.03862 | DZ8: 546.94979 | EA8: 543.54413 | EB8: 493.62997 | EC8: 419.93622 | ED8: 556.46179 | EE8: 588.25464 | EF8: 573.0381 | EG8: 563.6047 | EH8: 560.02961 | EI8: 508.54237 | EJ8: 432.5724 | EK8: 573.14047 | EL8: 605.81741 | EM8: 590.08005 | EN8: 580.30121 | EO8: 576.55625 | EP8: 523.49199 | EQ8: 445.24011 | ER8: 589.86075 | ES8: 623.42396 | ET8: 607.16447 | EU8: 597.03932 | EV8: 593.12404 | EW8: 538.47883 | EX8: 456.80436 | EY8: 603.62696 | EZ8: 636.34342 | FA8: 618.17163 | FB8: 606.32568 | FC8: 600.83399 | FD8: 544.113 | FE8: 461.57839 | FF8: 609.92807 | FG8: 642.97832 | FH8: 624.60957 | FI8: 612.63293 | FJ8: 607.07688 | FK8: 549.75999 | FL8: 466.36327 | FM8: 616.24351 | FN8: 649.6283 | FO8: 631.06214 | FP8: 618.95451 | FQ8: 613.33394 | FR8: 555.4198 | FS8: 471.15902 | FT8: 622.57328 | FU8: 656.29337 | FV8: 637.52935 | FW8: 625.29042 | FX8: 619.60517 | FY8: 561.09243 | FZ8: 475.96562 | GA8: 628.91737 | GB8: 661.73763 | GC8: 641.61311 | GD8: 628.11707 | GE8: 621.24107 | GF8: 561.52148 | GG8: 475.43911 | GH8: 627.04802 | GI8: 659.76885 | GJ8: 639.70239 | GK8: 626.24475 | GL8: 619.38748 | GM8: 559.84447 | GN8: 474.01784 | GO8: 625.17174 | GP8: 657.79277 | GQ8: 637.78458 | GR8: 624.3655 | GS8: 617.52703 | GT8: 558.16126 | GU8: 472.59131 | GV8: 623.28853 | GW8: 655.8094 | GX8: 635.8597 | GY8: 622.47931 | GZ8: 615.65972 | HA8: 556.47185 | HB8: 471.15953 | HC8: 621.39838 | HD8: 653.81873 | HE8: 633.92774 | HF8: 620.5862 | HG8: 613.78555 | HH8: 554.77624 | HI8: 469.7225 | HJ8: 619.5013 | HK8: 651.82076 | HL8: 631.9887 | HM8: 618.68614 | HN8: 611.90452 | HO8: 553.07442 | HP8: 468.2802 | HQ8: 617.59729 | HR8: 649.8155 | HS8: 630.04258 | HT8: 616.77916 | HU8: 610.01663 | HV8: 551.3664 | HW8: 466.83266 | HX8: 615.68634 | HY8: 647.80293 | HZ8: 628.08938 | IA8: 614.86524 | IB8: 608.12188 | IC8: 549.65218 | ID8: 465.37986 | IE8: 613.76847 | IF8: 645.78307 | IG8: 626.12911 | IH8: 612.9444 | II8: 606.22027 | IJ8: 547.93175 | IK8: 463.92181 | IL8: 613.0312 | IM8: 646.25646 | IN8: 627.80072 | IO8: 615.7694 | IP8: 610.19131 | IQ8: 552.58618 | IR8: 468.76564 | IS8: 619.42442 | IT8: 652.98832 | IU8: 634.33271 | IV8: 622.16875 | IW8: 616.52534 | IX8: 558.31559 | IY8: 473.62034 | IZ8: 625.83196 | JA8: 659.73526 | JB8: 640.87933 | JC8: 628.58244 | JD8: 622.87354 | JE8: 564.05781 | JF8: 478.48589 | JG8: 632.25384 | JH8: 666.49728 | JI8: 647.44058 | JJ8: 635.01045 | JK8: 629.23591 | JL8: 569.81285 | JM8: 483.3623 | JN8: 638.69004 | JO8: 673.27438 | JP8: 653.19483 | JQ8: 639.84313 | JR8: 633.22294 | JS8: 572.69921 | JT8: 485.19801 | JU8: 640.30805 | JV8: 674.13083 | JW8: 654.02558 | JX8: 640.65675 | JY8: 634.028 | JZ8: 573.42719 | KA8: 485.81465 | KB8: 641.12167 | KC8: 674.98727 | KD8: 654.85633 | KE8: 641.47037 | KF8: 634.83306 | KG8: 574.15516 | KH8: 486.43129 | KI8: 641.93529 | KJ8: 675.84371 | KK8: 655.68708 | KL8: 642.28399 | KM8: 635.63811 | KN8: 574.88314 | KO8: 487.04793 | KP8: 642.74891 | KQ8: 676.70015 | KR8: 656.51783 | KS8: 643.09761 | KT8: 636.44317 | KU8: 575.97314 | KV8: 488.27798 | KW8: 644.7768 | KX8: 679.26114 | KY8: 659.41571 | KZ8: 646.34108 | LA8: 640.05372 | LB8: 579.23891 | LC8: 491.04506 | LD8: 648.42883 | LE8: 683.10646 | LF8: 663.14672 | LG8: 649.99618 | LH8: 643.67136 | LI8: 582.5111 | LJ8: 493.81757 | LK8: 652.08803 | LL8: 686.95932 | LM8: 666.88504 | LN8: 653.65845 | LO8: 647.29609 | LP8: 585.78969 | LQ8: 496.59551 | LR8: 655.75439 | LS8: 690.81973 | LT8: 670.63067 | LU8: 657.32788 | LV8: 650.9279 | LW8: 589.0747 | LX8: 499.37888 | LY8: 657.05271 | LZ8: 689.68634 | MA8: 667.10538 | MB8: 651.49853 | MC8: 642.80735 | MD8: 579.60355 | ME8: 489.553 | MF8: 644.08305 | MG8: 676.02886 | MH8: 653.85257 | MI8: 638.51402 | MJ8: 629.95462 | MK8: 567.97697 | ML8: 479.70085 | MM8: 631.07874 | MN8: 662.33489 | MO8: 640.56436 | MP8: 625.49485 | MQ8: 617.06759 | MR8: 556.31938 | MS8: 469.82243 | MT8: 618.03976 | MU8: 648.60444 | MV8: 627.24076 | MW8: 612.44101 | MX8: 604.14626 | MY8: 544.63077 | MZ8: 459.91773 | NA8: 636.80643 | NB8: 603.09562
A9: 665.1047 | B9: 700.63356 | C9: 680.12234 | D9: 666.59667 | E9: 660.07223 | F9: 597.31917 | G9: 506.34182 | H9: 668.58794 | I9: 704.30117 | J9: 683.68094 | K9: 670.08288 | L9: 663.52272 | M9: 600.44019 | N9: 508.98626 | O9: 672.07811 | P9: 707.97607 | Q9: 687.24661 | R9: 673.57602 | S9: 666.98007 | T9: 603.5674 | U9: 511.63594 | V9: 675.57521 | W9: 711.65828 | X9: 690.81936 | Y9: 677.07609 | Z9: 670.44429 | AA9: 606.70082 | AB9: 514.29088 | AC9: 679.07925 | AD9: 715.34778 | AE9: 694.39919 | AF9: 680.5831 | AG9: 672.36613 | AH9: 607.03811 | AI9: 513.38979 | AJ9: 676.3238 | AK9: 710.79773 | AL9: 688.38493 | AM9: 673.12456 | AN9: 664.98295 | AO9: 600.359 | AP9: 507.72978 | AQ9: 668.85256 | AR9: 702.92992 | AS9: 680.74991 | AT9: 665.64379 | AU9: 657.57778 | AV9: 593.65999 | AW9: 502.05292 | AX9: 661.35908 | AY9: 695.0387 | AZ9: 673.09219 | BA9: 658.14078 | BB9: 650.15061 | BC9: 586.94109 | BD9: 496.35921 | BE9: 653.84336 | BF9: 687.12408 | BG9: 665.41177 | BH9: 650.61554 | BI9: 642.70144 | BJ9: 580.94124 | BK9: 491.90075 | BL9: 648.78401 | BM9: 682.66544 | BN9: 661.92819 | BO9: 648.02806 | BP9: 640.9571 | BQ9: 579.36303 | BR9: 490.56316 | BS9: 647.01814 | BT9: 680.80559 | BU9: 660.12312 | BV9: 646.25922 | BW9: 639.20589 | BX9: 577.7786 | BY9: 489.22031 | BZ9: 645.24534 | CA9: 678.93843 | CB9: 658.31097 | CC9: 644.48344 | CD9: 637.44783 | CE9: 576.18798 | CF9: 487.87221 | CG9: 643.4656 | CH9: 677.06398 | CI9: 656.49174 | CJ9: 642.70073 | CK9: 635.68291 | CL9: 574.59115 | CM9: 486.51885 | CN9: 641.67893 | CO9: 675.98791 | CP9: 656.22874 | CQ9: 643.20813 | CR9: 636.94217 | CS9: 576.41482 | CT9: 488.64402 | CU9: 645.24911 | CV9: 679.74707 | CW9: 659.87617 | CX9: 646.78138 | CY9: 640.47882 | CZ9: 579.61377 | DA9: 491.3545 | DB9: 648.82645 | DC9: 683.51377 | DD9: 663.53091 | DE9: 650.36179 | DF9: 644.02256 | DG9: 582.81913 | DH9: 494.0704 | DI9: 652.41096 | DJ9: 687.28802 | DK9: 667.19298 | DL9: 653.94937 | DM9: 647.57339 | DN9: 586.0309 | DO9: 496.79173 | DP9: 656.00263 | DQ9: 691.0698 | DR9: 670.86235 | DS9: 662.07402 | DT9: 660.09744 | DU9: 601.41286 | DV9: 513.25899 | DW9: 682.26796 | DX9: 723.49584 | DY9: 706.95231 | DZ9: 697.43273 | EA9: 695.09669 | EB9: 633.07264 | EC9: 540.08644 | ED9: 717.67817 | EE9: 760.7833 | EF9: 743.13429 | EG9: 732.88157 | EH9: 730.18512 | EI9: 664.81306 | EJ9: 566.9822 | EK9: 753.17851 | EL9: 798.16563 | EM9: 779.40829 | EN9: 768.42053 | EO9: 765.36273 | EP9: 696.63412 | EQ9: 593.94627 | ER9: 788.76898 | ES9: 835.64283 | ET9: 815.77432 | EU9: 804.04962 | EV9: 800.62951 | EW9: 728.53582 | EX9: 619.91098 | EY9: 821.63159 | EZ9: 868.76463 | FA9: 846.47563 | FB9: 832.71996 | FC9: 827.61431 | FD9: 751.68524 | FE9: 639.52687 | FF9: 847.52289 | FG9: 896.02832 | FH9: 872.93082 | FI9: 858.63889 | FJ9: 853.26953 | FK9: 774.89234 | FL9: 659.19164 | FM9: 873.47866 | FN9: 923.35988 | FO9: 899.45184 | FP9: 884.6223 | FQ9: 878.98854 | FR9: 798.15713 | FS9: 678.90527 | FT9: 899.49891 | FU9: 950.75932 | FV9: 926.03869 | FW9: 910.67018 | FX9: 904.77134 | FY9: 821.47962 | FZ9: 698.66776 | GA9: 925.58363 | GB9: 974.07561 | GC9: 944.63694 | GD9: 924.9478 | GE9: 915.00152 | GF9: 827.20498 | GG9: 700.53021 | GH9: 924.09805 | GI9: 972.5108 | GJ9: 943.11806 | GK9: 923.45925 | GL9: 913.52765 | GM9: 825.87134 | GN9: 699.39979 | GO9: 922.60553 | GP9: 970.93868 | GQ9: 941.59209 | GR9: 921.96376 | GS9: 912.04692 | GT9: 824.5315 | GU9: 698.26412 | GV9: 921.10608 | GW9: 969.35927 | GX9: 940.05905 | GY9: 920.46133 | GZ9: 910.55934 | HA9: 823.18545 | HB9: 697.12319 | HC9: 919.59969 | HD9: 967.77256 | HE9: 938.51893 | HF9: 918.95198 | HG9: 907.54089 | HH9: 819.07653 | HI9: 692.47376 | HJ9: 911.92214 | HK9: 958.06622 | HL9: 927.52725 | HM9: 906.64233 | HN9: 895.35592 | HO9: 808.05377 | HP9: 683.13309 | HQ9: 899.59268 | HR9: 945.08263 | HS9: 914.92811 | HT9: 894.29802 | HU9: 883.13664 | HV9: 797 | HW9: 673.76614 | HX9: 887.22856 | HY9: 932.06255 | HZ9: 902.29358 | IA9: 881.91904 | IB9: 870.88307 | IC9: 785.91521 | ID9: 664.37291 | IE9: 874.82977 | IF9: 919.00599 | IG9: 889.62365 | IH9: 869.5054 | II9: 858.5952 | IJ9: 774.7994 | IK9: 654.95342 | IL9: 863.53224 | IM9: 908.30478 | IN9: 880.39911 | IO9: 861.60326 | IP9: 851.89695 | IQ9: 769.75626 | IR9: 651.54062 | IS9: 859.0272 | IT9: 903.56047 | IU9: 875.79504 | IV9: 857.09208 | IW9: 847.43122 | IX9: 765.71627 | IY9: 648.11696 | IZ9: 854.50782 | JA9: 898.80108 | JB9: 871.17634 | JC9: 852.56656 | JD9: 842.95132 | JE9: 761.66346 | JF9: 644.68244 | JG9: 849.97412 | JH9: 894.02661 | JI9: 866.54301 | JJ9: 848.02672 | JK9: 838.45724 | JL9: 757.59783 | JM9: 641.23706 | JN9: 845.42609 | JO9: 889.23705 | JP9: 860.72886 | JQ9: 841.18784 | JR9: 830.55738 | JS9: 749.42947 | JT9: 633.44955 | JU9: 834.00462 | JV9: 876.00742 | JW9: 847.89106 | JX9: 828.60979 | JY9: 818.10683 | JZ9: 738.16657 | KA9: 623.90545 | KB9: 821.40677 | KC9: 862.74131 | KD9: 835.01787 | KE9: 815.99707 | KF9: 805.62198 | KG9: 726.87264 | KH9: 614.33508 | KI9: 808.77424 | KJ9: 849.4387 | KK9: 822.10929 | KL9: 803.34969 | KM9: 793.10283 | KN9: 715.54771 | KO9: 604.73844 | KP9: 796.10706 | KQ9: 836.09961 | KR9: 809.16532 | KS9: 790.66765 | KT9: 780.54938 | KU9: 706.66752 | KV9: 599.31052 | KW9: 791.7093 | KX9: 834.381 | KY9: 810.32258 | KZ9: 794.56813 | LA9: 787.14775 | LB9: 712.63596 | LC9: 604.36769 | LD9: 798.384 | LE9: 841.40916 | LF9: 817.14198 | LG9: 801.24898 | LH9: 793.76029 | LI9: 718.61722 | LJ9: 609.43572 | LK9: 805.07303 | LL9: 848.4524 | LM9: 823.97601 | LN9: 807.94415 | LO9: 800.38701 | LP9: 724.61129 | LQ9: 614.51461 | LR9: 811.77639 | LS9: 855.51072 | LT9: 830.82467 | LU9: 814.65364 | LV9: 807.02791 | LW9: 730.61819 | LX9: 619.60436 | LY9: 814.13731 | LZ9: 853.41034 | MA9: 824.33771 | MB9: 803.94102 | MC9: 792.11298 | MD9: 713.22796 | ME9: 601.56627 | MF9: 790.32814 | MG9: 828.33867 | MH9: 800.00909 | MI9: 780.10511 | MJ9: 768.51915 | MK9: 691.88514 | ML9: 583.48089 | MM9: 766.45657 | MN9: 803.20132 | MO9: 775.61676 | MP9: 756.2068 | MQ9: 744.86358 | MR9: 670.48649 | MS9: 565.34822 | MT9: 742.52261 | MU9: 777.99829 | MV9: 751.16072 | MW9: 732.2461 | MX9: 721.14628 | MY9: 649.03201 | MZ9: 547.16826 | NA9: 756.34342 | NB9: 715.09311
